Workbook

Sheet Config
A1: Migration Project Dashboard
A2: Enter project names, start dates, and speed. Add team members at right — they populate the Sign-Off dropdown on every project sheet.
A3: Early/On Time | B3: +1d late | C3: +2d | D3: +3d | E3: +4d | F3: +5d | G3: Status Complete gated via red highlights. Completed date is manual (static). Hours = |Completed - Target| × 24.
N4: Team Members
A5: # | B5: Project Name | C5: Start Date | D5: Speed | E5: Mult | F5: Target End | G5: Days | H5: % Complete | I5: Completed | J5: Avg Drift | K5: Status | L5: Sheet | N5: Name | O5: Role
A6: 1 | E6: =IF(D6="Normal",1,IF(D6="Express",0.5,IF(D6="Extended",1.5,""))) | F6: =IF(C6="","",C6+ROUND(14*E6,0)) | G6: =IF(E6="","",ROUND(14*E6,0)) | H6: =IFERROR('Project 1'!J53,"") -> 0 | I6: =IFERROR('Project 1'!M53,"") -> 0 | J6: =IFERROR('Project 1'!N54,"") | L6: Project 1
A7: 2 | E7: =IF(D7="Normal",1,IF(D7="Express",0.5,IF(D7="Extended",1.5,""))) | F7: =IF(C7="","",C7+ROUND(14*E7,0)) | G7: =IF(E7="","",ROUND(14*E7,0)) | H7: =IFERROR('Project 2'!J53,"") -> 0 | I7: =IFERROR('Project 2'!M53,"") -> 0 | J7: =IFERROR('Project 2'!N54,"") | L7: Project 2
A8: 3 | E8: =IF(D8="Normal",1,IF(D8="Express",0.5,IF(D8="Extended",1.5,""))) | F8: =IF(C8="","",C8+ROUND(14*E8,0)) | G8: =IF(E8="","",ROUND(14*E8,0)) | H8: =IFERROR('Project 3'!J53,"") -> 0 | I8: =IFERROR('Project 3'!M53,"") -> 0 | J8: =IFERROR('Project 3'!N54,"") | L8: Project 3
A9: 4 | E9: =IF(D9="Normal",1,IF(D9="Express",0.5,IF(D9="Extended",1.5,""))) | F9: =IF(C9="","",C9+ROUND(14*E9,0)) | G9: =IF(E9="","",ROUND(14*E9,0)) | H9: =IFERROR('Project 4'!J53,"") -> 0 | I9: =IFERROR('Project 4'!M53,"") -> 0 | J9: =IFERROR('Project 4'!N54,"") | L9: Project 4
A10: 5 | E10: =IF(D10="Normal",1,IF(D10="Express",0.5,IF(D10="Extended",1.5,""))) | F10: =IF(C10="","",C10+ROUND(14*E10,0)) | G10: =IF(E10="","",ROUND(14*E10,0)) | H10: =IFERROR('Project 5'!J53,"") -> 0 | I10: =IFERROR('Project 5'!M53,"") -> 0 | J10: =IFERROR('Project 5'!N54,"") | L10: Project 5
A11: 6 | E11: =IF(D11="Normal",1,IF(D11="Express",0.5,IF(D11="Extended",1.5,""))) | F11: =IF(C11="","",C11+ROUND(14*E11,0)) | G11: =IF(E11="","",ROUND(14*E11,0)) | H11: =IFERROR('Project 6'!J53,"") -> 0 | I11: =IFERROR('Project 6'!M53,"") -> 0 | J11: =IFERROR('Project 6'!N54,"") | L11: Project 6
A12: 7 | E12: =IF(D12="Normal",1,IF(D12="Express",0.5,IF(D12="Extended",1.5,""))) | F12: =IF(C12="","",C12+ROUND(14*E12,0)) | G12: =IF(E12="","",ROUND(14*E12,0)) | H12: =IFERROR('Project 7'!J53,"") -> 0 | I12: =IFERROR('Project 7'!M53,"") -> 0 | J12: =IFERROR('Project 7'!N54,"") | L12: Project 7
A13: 8 | E13: =IF(D13="Normal",1,IF(D13="Express",0.5,IF(D13="Extended",1.5,""))) | F13: =IF(C13="","",C13+ROUND(14*E13,0)) | G13: =IF(E13="","",ROUND(14*E13,0)) | H13: =IFERROR('Project 8'!J53,"") -> 0 | I13: =IFERROR('Project 8'!M53,"") -> 0 | J13: =IFERROR('Project 8'!N54,"") | L13: Project 8
A14: 9 | E14: =IF(D14="Normal",1,IF(D14="Express",0.5,IF(D14="Extended",1.5,""))) | F14: =IF(C14="","",C14+ROUND(14*E14,0)) | G14: =IF(E14="","",ROUND(14*E14,0)) | H14: =IFERROR('Project 9'!J53,"") -> 0 | I14: =IFERROR('Project 9'!M53,"") -> 0 | J14: =IFERROR('Project 9'!N54,"") | L14: Project 9
A15: 10 | E15: =IF(D15="Normal",1,IF(D15="Express",0.5,IF(D15="Extended",1.5,""))) | F15: =IF(C15="","",C15+ROUND(14*E15,0)) | G15: =IF(E15="","",ROUND(14*E15,0)) | H15: =IFERROR('Project 10'!J53,"") -> 0 | I15: =IFERROR('Project 10'!M53,"") -> 0 | J15: =IFERROR('Project 10'!N54,"") | L15: Project 10
A16: 11 | E16: =IF(D16="Normal",1,IF(D16="Express",0.5,IF(D16="Extended",1.5,""))) | F16: =IF(C16="","",C16+ROUND(14*E16,0)) | G16: =IF(E16="","",ROUND(14*E16,0)) | H16: =IFERROR('Project 11'!J53,"") -> 0 | I16: =IFERROR('Project 11'!M53,"") -> 0 | J16: =IFERROR('Project 11'!N54,"") | L16: Project 11
A17: 12 | E17: =IF(D17="Normal",1,IF(D17="Express",0.5,IF(D17="Extended",1.5,""))) | F17: =IF(C17="","",C17+ROUND(14*E17,0)) | G17: =IF(E17="","",ROUND(14*E17,0)) | H17: =IFERROR('Project 12'!J53,"") -> 0 | I17: =IFERROR('Project 12'!M53,"") -> 0 | J17: =IFERROR('Project 12'!N54,"") | L17: Project 12
A18: 13 | E18: =IF(D18="Normal",1,IF(D18="Express",0.5,IF(D18="Extended",1.5,""))) | F18: =IF(C18="","",C18+ROUND(14*E18,0)) | G18: =IF(E18="","",ROUND(14*E18,0)) | H18: =IFERROR('Project 13'!J53,"") -> 0 | I18: =IFERROR('Project 13'!M53,"") -> 0 | J18: =IFERROR('Project 13'!N54,"") | L18: Project 13
A19: 14 | E19: =IF(D19="Normal",1,IF(D19="Express",0.5,IF(D19="Extended",1.5,""))) | F19: =IF(C19="","",C19+ROUND(14*E19,0)) | G19: =IF(E19="","",ROUND(14*E19,0)) | H19: =IFERROR('Project 14'!J53,"") -> 0 | I19: =IFERROR('Project 14'!M53,"") -> 0 | J19: =IFERROR('Project 14'!N54,"") | L19: Project 14
A21: PORTFOLIO TOTALS | H21: =IFERROR(AVERAGE(H6:H19),"") -> 0 | I21: =SUM(I6:I19) -> 0 | J21: =IFERROR(AVERAGE(J6:J19),"") | K21: =COUNTIF(K6:K19,"Complete")&"/"&COUNTA(B6:B19) -> 0/0
A23: Portfolio Progress — % Complete by Project

Sheet Project 1
A1: =IF(Config!B6<>"",Config!B6&" — DNS, Certificate & SSO Migration Runbook","Project 1 — Assign name on Config sheet") -> Project 1 — Assign name on Config sheet
A3: Start Date: | C3: =Config!C6 -> 0 | D3: Speed: | E3: =Config!D6 -> 0 | G3: Mult: | H3: =Config!E6 | I3: Target End: | K3: =Config!F6 | L3: Days: | M3: =Config!G6
A5: # | B5: Phase | C5: ID | D5: Task | E5: What Needs to Happen | F5: Owner | G5: Day | H5: Target Date | I5: Status | J5: % Complete | K5: Signed Off By | L5: Report Link | M5: Completed | N5: Drift | O5: Hrs | P5: JIRA | Q5: How We Know Its Done | R5: Rollback | S5: Notes
A6: 1 | B6: 1 — Discovery | C6: 1.1 | D6: Pull DNS Records | E6: Export all DNS records for the app domain — A, CNAME, MX, TXT, SRV, the works. Grab zone files from the provider. Document TTLs and anything pointing at a CDN or WAF. | F6: Migration Lead | G6: =ROUND(0*$H$3,0) -> #VALUE! | H6: =$C$3+G6 -> #VALUE! | J6: =IF(I6="Complete",1,IF(I6="Skipped",1,IF(I6="Blocked",0.5,IF(I6="In Progress",0.25,0)))) -> 0 | N6: =IF(M6="","",M6-H6) | O6: =IF(M6="","",ABS(M6-H6)*24) | Q6: Full DNS export in the repo, second set of eyes confirmed it | R6: N/A — just docs | S6: Get TTLs, record types, CDN refs
A7: 2 | B7: 1 — Discovery | C7: 1.2 | D7: Pull Current Certs | E7: Document every cert bound in IIS — subject, SANs, issuer, expiry, thumbprint. PowerShell: Get-ChildItem Cert:\LocalMachine\My | F7: Migration Lead | G7: =ROUND(0*$H$3,0) -> #VALUE! | H7: =$C$3+G7 -> #VALUE! | J7: =IF(I7="Complete",1,IF(I7="Skipped",1,IF(I7="Blocked",0.5,IF(I7="In Progress",0.25,0)))) -> 0 | N7: =IF(M7="","",M7-H7) | O7: =IF(M7="","",ABS(M7-H7)*24) | Q7: Cert inventory with thumbprints, SANs, expiry confirmed | R7: N/A — just docs | S7: Flag wildcards, intermediates, shared certs
A8: 3 | B8: 1 — Discovery | C8: 1.3 | D8: Export IIS Bindings | E8: Dump all IIS site bindings — IP, port, hostname, cert assignment. Get-WebBinding or appcmd. Both HTTP and HTTPS. | F8: Migration Lead | G8: =ROUND(0*$H$3,0) -> #VALUE! | H8: =$C$3+G8 -> #VALUE! | J8: =IF(I8="Complete",1,IF(I8="Skipped",1,IF(I8="Blocked",0.5,IF(I8="In Progress",0.25,0)))) -> 0 | N8: =IF(M8="","",M8-H8) | O8: =IF(M8="","",ABS(M8-H8)*24) | Q8: Binding export saved, mapped to DNS records and certs | R8: N/A — just docs | S8: Watch for SNI, IP-specific bindings, weird ports
A9: 4 | B9: 1 — Discovery | C9: 1.4 | D9: Map Application Dependencies | E9: Find every reference to the current domain — connection strings, API endpoints, OAuth redirect URIs, CORS policies, webhooks, hardcoded URLs. Check web.config, appsettings.json, registry, env vars, and anything external that calls back. | F9: Migration Lead | G9: =ROUND(1*$H$3,0) -> #VALUE! | H9: =$C$3+G9 -> #VALUE! | J9: =IF(I9="Complete",1,IF(I9="Skipped",1,IF(I9="Blocked",0.5,IF(I9="In Progress",0.25,0)))) -> 0 | N9: =IF(M9="","",M9-H9) | O9: =IF(M9="","",ABS(M9-H9)*24) | Q9: Dependency matrix done, every old-domain ref catalogued with file path | R9: N/A — just docs | S9: External services with callback URLs are the ones that bite you
A10: 5 | B10: 1 — Discovery | C10: 1.5 | D10: Map SSO / IdP Configuration | E10: Document current SSO setup — identity provider, protocol (SAML/OIDC), client IDs, redirect URIs, metadata URLs, token endpoints, claim mappings, and any app registrations tied to the domain. If ADFS, pull the relying party trust config. | F10: Migration Lead | G10: =ROUND(1*$H$3,0) -> #VALUE! | H10: =$C$3+G10 -> #VALUE! | J10: =IF(I10="Complete",1,IF(I10="Skipped",1,IF(I10="Blocked",0.5,IF(I10="In Progress",0.25,0)))) -> 0 | N10: =IF(M10="","",M10-H10) | O10: =IF(M10="","",ABS(M10-H10)*24) | Q10: SSO config fully documented — IdP settings, redirect URIs, client IDs, claim maps all captured | R10: N/A — just docs | S10: Dont forget logout/post-logout redirect URIs, they always get missed
A11: 6 | B11: 1 — Discovery | C11: 1.6 | D11: Confirm Static IPs | E11: Verify the VM and DB IPs are static, not DHCP. Document both. No IP change here. | F11: Migration Lead | G11: =ROUND(1*$H$3,0) -> #VALUE! | H11: =$C$3+G11 -> #VALUE! | J11: =IF(I11="Complete",1,IF(I11="Skipped",1,IF(I11="Blocked",0.5,IF(I11="In Progress",0.25,0)))) -> 0 | N11: =IF(M11="","",M11-H11) | O11: =IF(M11="","",ABS(M11-H11)*24) | Q11: ipconfig /all saved, static confirmed for app and DB | R11: N/A — just docs | S11: If DHCP, fix it before anything else
A12: 7 | B12: 1 — Discovery | C12: 1.7 | D12: Check Firewall & Network Rules | E12: Audit firewall rules, NSGs, LB configs for anything referencing the FQDN. Make sure nothing breaks with the new domain. | F12: Network Admin | G12: =ROUND(1*$H$3,0) -> #VALUE! | H12: =$C$3+G12 -> #VALUE! | J12: =IF(I12="Complete",1,IF(I12="Skipped",1,IF(I12="Blocked",0.5,IF(I12="In Progress",0.25,0)))) -> 0 | N12: =IF(M12="","",M12-H12) | O12: =IF(M12="","",ABS(M12-H12)*24) | Q12: All rules reviewed, mitigation plan for any FQDN-dependent rules | R12: N/A — just docs | S12: Some firewalls resolve DNS at rule creation, prefer IP rules
A13: 8 | B13: 1 — Discovery | C13: 1.8 | D13: Get New Certs | E13: Request new certs for target domain from the CA. All required SANs included. Validate the chain is complete — root, intermediate, leaf. | F13: Migration Lead | G13: =ROUND(1*$H$3,0) -> #VALUE! | H13: =$C$3+G13 -> #VALUE! | J13: =IF(I13="Complete",1,IF(I13="Skipped",1,IF(I13="Blocked",0.5,IF(I13="In Progress",0.25,0)))) -> 0 | N13: =IF(M13="","",M13-H13) | O13: =IF(M13="","",ABS(M13-H13)*24) | Q13: PFX in hand, chain validated via certutil, SANs match | R13: Can revert to old cert | S13: If ACME/Lets Encrypt, test issuance in lower env first
A14: 9 | B14: 1 — Discovery | C14: 1.9 | D14: Write Rollback Plan | E14: Step-by-step rollback doc — DNS revert, old cert re-bind, IIS restore, config restore, comms plan. Pre-stage everything. | F14: Migration Lead | G14: =ROUND(2*$H$3,0) -> #VALUE! | H14: =$C$3+G14 -> #VALUE! | J14: =IF(I14="Complete",1,IF(I14="Skipped",1,IF(I14="Blocked",0.5,IF(I14="In Progress",0.25,0)))) -> 0 | N14: =IF(M14="","",M14-H14) | O14: =IF(M14="","",ABS(M14-H14)*24) | Q14: Rollback plan reviewed and approved, all artifacts accessible | R14: N/A — this IS the rollback plan | S14: Pre-write the rollback PowerShell scripts
A15: 10 | B15: 1 — Discovery | C15: 1.10 | D15: Schedule Maintenance Window | E15: Coordinate the migration window. Notify stakeholders, upstream/downstream system owners. | F15: PM | G15: =ROUND(2*$H$3,0) -> #VALUE! | H15: =$C$3+G15 -> #VALUE! | J15: =IF(I15="Complete",1,IF(I15="Skipped",1,IF(I15="Blocked",0.5,IF(I15="In Progress",0.25,0)))) -> 0 | N15: =IF(M15="","",M15-H15) | O15: =IF(M15="","",ABS(M15-H15)*24) | Q15: Calendar invites sent, window approved, everyone acknowledged | R15: N/A | S15: Time zones, business hours, SLA stuff
A16: 11 | B16: 2 — Backups | C16: 2.1 | D16: Backup IIS Config | E16: appcmd add backup. Grab applicationHost.config and all web.configs. | F16: Migration Lead | G16: =ROUND(3*$H$3,0) -> #VALUE! | H16: =$C$3+G16 -> #VALUE! | J16: =IF(I16="Complete",1,IF(I16="Skipped",1,IF(I16="Blocked",0.5,IF(I16="In Progress",0.25,0)))) -> 0 | N16: =IF(M16="","",M16-H16) | O16: =IF(M16="","",ABS(M16-H16)*24) | Q16: Backup verified via dry-run restore, in the repo | R16: Restore IIS from backup | S16: appcmd add backup 'PreMigration'
A17: 12 | B17: 2 — Backups | C17: 2.2 | D17: Export Certs as PFX | E17: Export all relevant certs with private keys as PFX. Store securely, document the passwords separately. | F17: Migration Lead | G17: =ROUND(3*$H$3,0) -> #VALUE! | H17: =$C$3+G17 -> #VALUE! | J17: =IF(I17="Complete",1,IF(I17="Skipped",1,IF(I17="Blocked",0.5,IF(I17="In Progress",0.25,0)))) -> 0 | N17: =IF(M17="","",M17-H17) | O17: =IF(M17="","",ABS(M17-H17)*24) | Q17: PFX files verified importable on test system, in the vault | R17: Re-import old certs from PFX | S17: Export-PfxCertificate with a strong password
A18: 13 | B18: 2 — Backups | C18: 2.3 | D18: Backup App Config | E18: Copy web.config, appsettings.json, env vars, registry keys. Everything. | F18: Migration Lead | G18: =ROUND(3*$H$3,0) -> #VALUE! | H18: =$C$3+G18 -> #VALUE! | J18: =IF(I18="Complete",1,IF(I18="Skipped",1,IF(I18="Blocked",0.5,IF(I18="In Progress",0.25,0)))) -> 0 | N18: =IF(M18="","",M18-H18) | O18: =IF(M18="","",ABS(M18-H18)*24) | Q18: Config backup diffed against live, stored in repo | R18: Restore configs from backup | S18: Include transform files
A19: 14 | B19: 2 — Backups | C19: 2.4 | D19: Backup DNS Records | E19: Export or screenshot DNS records from the provider. Zone file if available. | F19: Migration Lead | G19: =ROUND(3*$H$3,0) -> #VALUE! | H19: =$C$3+G19 -> #VALUE! | J19: =IF(I19="Complete",1,IF(I19="Skipped",1,IF(I19="Blocked",0.5,IF(I19="In Progress",0.25,0)))) -> 0 | N19: =IF(M19="","",M19-H19) | O19: =IF(M19="","",ABS(M19-H19)*24) | Q19: Zone file saved and readable | R19: Revert DNS from backup | S19: Some providers support zone import for quick rollback
A20: 15 | B20: 2 — Backups | C20: 2.5 | D20: Export SSO / IdP Configuration | E20: Export the current IdP app registration, relying party trust, or OIDC client config. Screenshot or export the claim mappings, redirect URIs, and any conditional access policies tied to this app. | F20: Migration Lead | G20: =ROUND(3*$H$3,0) -> #VALUE! | H20: =$C$3+G20 -> #VALUE! | J20: =IF(I20="Complete",1,IF(I20="Skipped",1,IF(I20="Blocked",0.5,IF(I20="In Progress",0.25,0)))) -> 0 | N20: =IF(M20="","",M20-H20) | O20: =IF(M20="","",ABS(M20-H20)*24) | Q20: SSO config export saved alongside other backups, verified re-importable | R20: Restore IdP config from export | S20: Azure AD: export app manifest JSON. ADFS: export relying party trust XML
A21: 16 | B21: 2 — Backups | C21: 2.6 | D21: VM Snapshot | E21: Hypervisor snapshot of the VM. Verify its valid. | F21: Infra Admin | G21: =ROUND(3*$H$3,0) -> #VALUE! | H21: =$C$3+G21 -> #VALUE! | J21: =IF(I21="Complete",1,IF(I21="Skipped",1,IF(I21="Blocked",0.5,IF(I21="In Progress",0.25,0)))) -> 0 | N21: =IF(M21="","",M21-H21) | O21: =IF(M21="","",ABS(M21-H21)*24) | Q21: Snapshot in hypervisor, revert function confirmed | R21: Revert entire VM to snapshot | S21: Nuclear option — make sure theres disk space
A22: 17 | B22: 3 — Cutover | C22: 3.1 | D22: Import New Cert | E22: Import PFX into Local Machine Personal store. Full chain — intermediate + root if needed. | F22: Migration Lead | G22: =ROUND(4*$H$3,0) -> #VALUE! | H22: =$C$3+G22 -> #VALUE! | J22: =IF(I22="Complete",1,IF(I22="Skipped",1,IF(I22="Blocked",0.5,IF(I22="In Progress",0.25,0)))) -> 0 | N22: =IF(M22="","",M22-H22) | O22: =IF(M22="","",ABS(M22-H22)*24) | Q22: Cert visible in certlm.msc, chain shows OK | R22: Remove new cert, old binding stays | S22: Import-PfxCertificate -CertStoreLocation Cert:\LocalMachine\My
A23: 18 | B23: 3 — Cutover | C23: 3.2 | D23: Verify Cert Chain | E23: Make sure the full chain is trusted. Intermediates and root in the right stores. | F23: Migration Lead | G23: =ROUND(4*$H$3,0) -> #VALUE! | H23: =$C$3+G23 -> #VALUE! | J23: =IF(I23="Complete",1,IF(I23="Skipped",1,IF(I23="Blocked",0.5,IF(I23="In Progress",0.25,0)))) -> 0 | N23: =IF(M23="","",M23-H23) | O23: =IF(M23="","",ABS(M23-H23)*24) | Q23: certutil -verify -urlfetch passes clean | R23: Install missing chain certs
A24: 19 | B24: 3 — Cutover | C24: 3.3 | D24: Update IIS Bindings | E24: Swap the HTTPS binding to the new cert and new hostname. Same IP, same port. SNI if applicable. | F24: Migration Lead | G24: =ROUND(4*$H$3,0) -> #VALUE! | H24: =$C$3+G24 -> #VALUE! | J24: =IF(I24="Complete",1,IF(I24="Skipped",1,IF(I24="Blocked",0.5,IF(I24="In Progress",0.25,0)))) -> 0 | N24: =IF(M24="","",M24-H24) | O24: =IF(M24="","",ABS(M24-H24)*24) | Q24: Get-WebBinding shows new cert + hostname, netsh confirms | R24: Revert binding from backup 2.1 | S24: Set-WebBinding + netsh http add sslcert
A25: 20 | B25: 3 — Cutover | C25: 3.4 | D25: Update App Config | E25: Flip all config files to the new domain — base URLs, CORS origins, OAuth redirects, cookie domains, absolute URLs. | F25: Migration Lead | G25: =ROUND(4*$H$3,0) -> #VALUE! | H25: =$C$3+G25 -> #VALUE! | J25: =IF(I25="Complete",1,IF(I25="Skipped",1,IF(I25="Blocked",0.5,IF(I25="In Progress",0.25,0)))) -> 0 | N25: =IF(M25="","",M25-H25) | O25: =IF(M25="","",ABS(M25-H25)*24) | Q25: Config diff shows only expected changes, findstr confirms no old domain refs | R25: Restore from backup 2.3 | S25: grep/findstr for old domain across everything to verify
A26: 21 | B26: 3 — Cutover | C26: 3.5 | D26: Update SSO / IdP Registration | E26: Update the identity provider app registration with new redirect URIs, post-logout URIs, and identifier URIs for the new domain. Update SAML metadata endpoint if applicable. | F26: Migration Lead | G26: =ROUND(4*$H$3,0) -> #VALUE! | H26: =$C$3+G26 -> #VALUE! | J26: =IF(I26="Complete",1,IF(I26="Skipped",1,IF(I26="Blocked",0.5,IF(I26="In Progress",0.25,0)))) -> 0 | N26: =IF(M26="","",M26-H26) | O26: =IF(M26="","",ABS(M26-H26)*24) | Q26: IdP shows correct new-domain URIs, metadata endpoint resolves, no old domain refs | R26: Revert IdP config from backup 2.5 | S26: Azure AD: update redirect URIs. ADFS: update relying party trust. Okta: update app integration URIs
A27: 22 | B27: 3 — Cutover | C27: 3.6 | D27: Update App SSO Config | E27: Update the applications SSO config to match — client metadata URL, authority/issuer, SAML assertion consumer service URL, OIDC redirect URI in web.config or appsettings. Token validation audience needs to match. | F27: Migration Lead | G27: =ROUND(4*$H$3,0) -> #VALUE! | H27: =$C$3+G27 -> #VALUE! | J27: =IF(I27="Complete",1,IF(I27="Skipped",1,IF(I27="Blocked",0.5,IF(I27="In Progress",0.25,0)))) -> 0 | N27: =IF(M27="","",M27-H27) | O27: =IF(M27="","",ABS(M27-H27)*24) | Q27: App SSO config points to correct IdP endpoints with new domain URIs, token audience matches | R27: Restore app config from backup 2.3 | S27: Easy to miss the WS-Federation wtrealm or SAML entityID
A28: 23 | B28: 3 — Cutover | C28: 3.7 | D28: Update DNS | E28: Point the new domain at the VMs IP. Short TTL (60-300s) in lower env, or pre-lowered in prod. | F28: Migration Lead | G28: =ROUND(5*$H$3,0) -> #VALUE! | H28: =$C$3+G28 -> #VALUE! | J28: =IF(I28="Complete",1,IF(I28="Skipped",1,IF(I28="Blocked",0.5,IF(I28="In Progress",0.25,0)))) -> 0 | N28: =IF(M28="","",M28-H28) | O28: =IF(M28="","",ABS(M28-H28)*24) | Q28: nslookup resolves new domain to correct IP | R28: Revert DNS from backup 2.4 | S28: Prod: lower TTL 24-48hrs ahead (see 5.1)
A29: 24 | B29: 3 — Cutover | C29: 3.8 | D29: Restart IIS | E29: iisreset, recycle the app pool. Pick up all changes cleanly. | F29: Migration Lead | G29: =ROUND(5*$H$3,0) -> #VALUE! | H29: =$C$3+G29 -> #VALUE! | J29: =IF(I29="Complete",1,IF(I29="Skipped",1,IF(I29="Blocked",0.5,IF(I29="In Progress",0.25,0)))) -> 0 | N29: =IF(M29="","",M29-H29) | O29: =IF(M29="","",ABS(M29-H29)*24) | Q29: Site running, app pool started, Event Viewer clean | R29: N/A — non-destructive | S29: Brief downtime during iisreset
A30: 25 | B30: 3 — Cutover | C30: 3.9 | D30: Verify DNS Propagation | E30: Check propagation across multiple resolvers. Dont move on until its solid. | F30: Migration Lead | G30: =ROUND(5*$H$3,0) -> #VALUE! | H30: =$C$3+G30 -> #VALUE! | J30: =IF(I30="Complete",1,IF(I30="Skipped",1,IF(I30="Blocked",0.5,IF(I30="In Progress",0.25,0)))) -> 0 | N30: =IF(M30="","",M30-H30) | O30: =IF(M30="","",ABS(M30-H30)*24) | Q30: Resolves from 3+ external resolvers and 2+ regions | R30: Wait or investigate cached TTL | S30: nslookup 8.8.8.8, 1.1.1.1, whatsmydns.net
A31: 26 | B31: 4 — Testing | C31: 4.1 | D31: Run Test Scripts | E31: Execute the full test suite — HTTPS/cert, redirects, auth flow including SSO login + 2FA, CRUD, DB connectivity, APIs, webhooks, email links, perf baseline, security scan. | F31: QA Lead | G31: =ROUND(6*$H$3,0) -> #VALUE! | H31: =$C$3+G31 -> #VALUE! | J31: =IF(I31="Complete",1,IF(I31="Skipped",1,IF(I31="Blocked",0.5,IF(I31="In Progress",0.25,0)))) -> 0 | N31: =IF(M31="","",M31-H31) | O31: =IF(M31="","",ABS(M31-H31)*24) | Q31: All scripts executed, results recorded, pass/fail documented per script | R31: Log failures, categorize migration vs pre-existing | S31: Update JIRA and this sheet with results
A32: 27 | B32: 4 — Testing | C32: 4.2 | D32: SSO End-to-End Validation | E32: Test the full SSO flow — IdP-initiated and SP-initiated login, token validation, claim mapping, group/role assignment, logout + single logout, session timeout, conditional access. | F32: QA Lead | G32: =ROUND(6*$H$3,0) -> #VALUE! | H32: =$C$3+G32 -> #VALUE! | J32: =IF(I32="Complete",1,IF(I32="Skipped",1,IF(I32="Blocked",0.5,IF(I32="In Progress",0.25,0)))) -> 0 | N32: =IF(M32="","",M32-H32) | O32: =IF(M32="","",ABS(M32-H32)*24) | Q32: SSO works both directions, claims correct, logout cleans sessions, no old domain in any redirect | R32: Check IdP logs for failed assertions or redirect mismatches | S32: Hit IdP login directly AND from the app, both need to work
A33: 28 | B33: 4 — Testing | C33: 4.3 | D33: Triage & Fix | E33: Review all failures. Migration-caused vs pre-existing. Fix whats ours, re-run the failed tests. | F33: Migration Lead | G33: =ROUND(7*$H$3,0) -> #VALUE! | H33: =$C$3+G33 -> #VALUE! | J33: =IF(I33="Complete",1,IF(I33="Skipped",1,IF(I33="Blocked",0.5,IF(I33="In Progress",0.25,0)))) -> 0 | N33: =IF(M33="","",M33-H33) | O33: =IF(M33="","",ABS(M33-H33)*24) | Q33: All migration defects fixed, re-runs pass, pre-existing issues documented | R33: If unfixable, assess rollback | S33: Pull in app team for code-level fixes if needed
A34: 29 | B34: 4 — Testing | C34: 4.4 | D34: Update JIRA & This Sheet | E34: Get JIRA current with test results, defect resolutions, evidence. Update Status column here for every task. | F34: QA Lead | G34: =ROUND(8*$H$3,0) -> #VALUE! | H34: =$C$3+G34 -> #VALUE! | J34: =IF(I34="Complete",1,IF(I34="Skipped",1,IF(I34="Blocked",0.5,IF(I34="In Progress",0.25,0)))) -> 0 | N34: =IF(M34="","",M34-H34) | O34: =IF(M34="","",ABS(M34-H34)*24) | Q34: JIRA tickets current, this sheet reflects actual status, evidence attached | R34: N/A — just docs | S34: Screenshots, logs, test exports attached to tickets
A35: 30 | B35: 4 — Testing | C35: 4.5 | D35: Sign-Off | E35: Collect results. Get formal sign-off from QA, app owner, stakeholders. | F35: PM | G35: =ROUND(8*$H$3,0) -> #VALUE! | H35: =$C$3+G35 -> #VALUE! | J35: =IF(I35="Complete",1,IF(I35="Skipped",1,IF(I35="Blocked",0.5,IF(I35="In Progress",0.25,0)))) -> 0 | N35: =IF(M35="","",M35-H35) | O35: =IF(M35="","",ABS(M35-H35)*24) | Q35: Written sign-off, all critical/high defects resolved, accepted risks documented | R35: Dont proceed, fix outstanding issues
A36: 31 | B36: 5 — Pre-Prod Prep | C36: 5.1 | D36: Lower Prod DNS TTL (24-48hrs Early) | E36: Drop TTL on the existing prod DNS record to 60-300s. At least 24-48hrs before the migration window. | F36: Migration Lead | G36: =ROUND(9*$H$3,0) -> #VALUE! | H36: =$C$3+G36 -> #VALUE! | J36: =IF(I36="Complete",1,IF(I36="Skipped",1,IF(I36="Blocked",0.5,IF(I36="In Progress",0.25,0)))) -> 0 | N36: =IF(M36="","",M36-H36) | O36: =IF(M36="","",ABS(M36-H36)*24) | Q36: dig shows reduced TTL, waited 2x old TTL | R36: Raise TTL back | S36: This MUST happen in advance, not day-of
A37: 32 | B37: 5 — Pre-Prod Prep | C37: 5.2 | D37: Confirm Window Is Active | E37: Verify the maintenance window is live. Final notification to stakeholders. On-call confirmed. | F37: PM | G37: =ROUND(10*$H$3,0) -> #VALUE! | H37: =$C$3+G37 -> #VALUE! | J37: =IF(I37="Complete",1,IF(I37="Skipped",1,IF(I37="Blocked",0.5,IF(I37="In Progress",0.25,0)))) -> 0 | N37: =IF(M37="","",M37-H37) | O37: =IF(M37="","",ABS(M37-H37)*24) | Q37: Notification sent, status page updated, on-call team confirmed | R37: Cancel window, send all-clear
A38: 33 | B38: 5 — Pre-Prod Prep | C38: 5.3 | D38: Prod VM Snapshot | E38: Snapshot immediately before touching anything. | F38: Infra Admin | G38: =ROUND(10*$H$3,0) -> #VALUE! | H38: =$C$3+G38 -> #VALUE! | J38: =IF(I38="Complete",1,IF(I38="Skipped",1,IF(I38="Blocked",0.5,IF(I38="In Progress",0.25,0)))) -> 0 | N38: =IF(M38="","",M38-H38) | O38: =IF(M38="","",ABS(M38-H38)*24) | Q38: Snapshot verified in hypervisor | R38: Revert to snapshot | S38: Check disk space first
A39: 34 | B39: 5 — Pre-Prod Prep | C39: 5.4 | D39: Backup Prod IIS, Certs, SSO & Config | E39: Repeat Phase 2 backup steps on production. | F39: Migration Lead | G39: =ROUND(10*$H$3,0) -> #VALUE! | H39: =$C$3+G39 -> #VALUE! | J39: =IF(I39="Complete",1,IF(I39="Skipped",1,IF(I39="Blocked",0.5,IF(I39="In Progress",0.25,0)))) -> 0 | N39: =IF(M39="","",M39-H39) | O39: =IF(M39="","",ABS(M39-H39)*24) | Q39: All backups created, verified, labelled with timestamp | R39: Restore from these backups
A40: 35 | B40: 6 — Prod Cutover | C40: 6.1 | D40: Execute Phase 3 on Production | E40: Run steps 3.1 through 3.9 on the prod VM. Exact same procedures validated in testing. No freelancing. | F40: Migration Lead | G40: =ROUND(10*$H$3,0) -> #VALUE! | H40: =$C$3+G40 -> #VALUE! | J40: =IF(I40="Complete",1,IF(I40="Skipped",1,IF(I40="Blocked",0.5,IF(I40="In Progress",0.25,0)))) -> 0 | N40: =IF(M40="","",M40-H40) | O40: =IF(M40="","",ABS(M40-H40)*24) | Q40: Cert, bindings, app config, SSO config, DNS all updated, IIS restarted, propagation confirmed | R40: Revert per rollback plan 1.9 | S40: Follow the validated playbook exactly
A41: 36 | B41: 7 — Prod Smoke | C41: 7.1 | D41: Run Smoke Scripts on Prod | E41: Smoke test subset against prod — HTTPS, redirects, SSO login (IdP and SP initiated), critical reads, critical writes, top APIs, external integrations, monitoring. | F41: QA Lead | G41: =ROUND(11*$H$3,0) -> #VALUE! | H41: =$C$3+G41 -> #VALUE! | J41: =IF(I41="Complete",1,IF(I41="Skipped",1,IF(I41="Blocked",0.5,IF(I41="In Progress",0.25,0)))) -> 0 | N41: =IF(M41="","",M41-H41) | O41: =IF(M41="","",ABS(M41-H41)*24) | Q41: All smoke scripts pass, results in JIRA and this sheet | R41: Log failures, assess rollback severity | S41: External network, multiple browsers, at least one mobile
A42: 37 | B42: 7 — Prod Smoke | C42: 7.2 | D42: Smoke Defect Triage | E42: Review failures. Fix immediately or pull the trigger on rollback. | F42: Migration Lead | G42: =ROUND(11*$H$3,0) -> #VALUE! | H42: =$C$3+G42 -> #VALUE! | J42: =IF(I42="Complete",1,IF(I42="Skipped",1,IF(I42="Blocked",0.5,IF(I42="In Progress",0.25,0)))) -> 0 | N42: =IF(M42="","",M42-H42) | O42: =IF(M42="","",ABS(M42-H42)*24) | Q42: All failures triaged, fixes applied or rollback initiated | R42: Execute rollback plan 1.9 | S42: Everyone on the call for this
...

Sheet Project 2
A1: =IF(Config!B7<>"",Config!B7&" — DNS, Certificate & SSO Migration Runbook","Project 2 — Assign name on Config sheet") -> Project 2 — Assign name on Config sheet
A3: Start Date: | C3: =Config!C7 -> 0 | D3: Speed: | E3: =Config!D7 -> 0 | G3: Mult: | H3: =Config!E7 | I3: Target End: | K3: =Config!F7 | L3: Days: | M3: =Config!G7
A5: # | B5: Phase | C5: ID | D5: Task | E5: What Needs to Happen | F5: Owner | G5: Day | H5: Target Date | I5: Status | J5: % Complete | K5: Signed Off By | L5: Report Link | M5: Completed | N5: Drift | O5: Hrs | P5: JIRA | Q5: How We Know Its Done | R5: Rollback | S5: Notes
A6: 1 | B6: 1 — Discovery | C6: 1.1 | D6: Pull DNS Records | E6: Export all DNS records for the app domain — A, CNAME, MX, TXT, SRV, the works. Grab zone files from the provider. Document TTLs and anything pointing at a CDN or WAF. | F6: Migration Lead | G6: =ROUND(0*$H$3,0) -> #VALUE! | H6: =$C$3+G6 -> #VALUE! | J6: =IF(I6="Complete",1,IF(I6="Skipped",1,IF(I6="Blocked",0.5,IF(I6="In Progress",0.25,0)))) -> 0 | N6: =IF(M6="","",M6-H6) | O6: =IF(M6="","",ABS(M6-H6)*24) | Q6: Full DNS export in the repo, second set of eyes confirmed it | R6: N/A — just docs | S6: Get TTLs, record types, CDN refs
A7: 2 | B7: 1 — Discovery | C7: 1.2 | D7: Pull Current Certs | E7: Document every cert bound in IIS — subject, SANs, issuer, expiry, thumbprint. PowerShell: Get-ChildItem Cert:\LocalMachine\My | F7: Migration Lead | G7: =ROUND(0*$H$3,0) -> #VALUE! | H7: =$C$3+G7 -> #VALUE! | J7: =IF(I7="Complete",1,IF(I7="Skipped",1,IF(I7="Blocked",0.5,IF(I7="In Progress",0.25,0)))) -> 0 | N7: =IF(M7="","",M7-H7) | O7: =IF(M7="","",ABS(M7-H7)*24) | Q7: Cert inventory with thumbprints, SANs, expiry confirmed | R7: N/A — just docs | S7: Flag wildcards, intermediates, shared certs
A8: 3 | B8: 1 — Discovery | C8: 1.3 | D8: Export IIS Bindings | E8: Dump all IIS site bindings — IP, port, hostname, cert assignment. Get-WebBinding or appcmd. Both HTTP and HTTPS. | F8: Migration Lead | G8: =ROUND(0*$H$3,0) -> #VALUE! | H8: =$C$3+G8 -> #VALUE! | J8: =IF(I8="Complete",1,IF(I8="Skipped",1,IF(I8="Blocked",0.5,IF(I8="In Progress",0.25,0)))) -> 0 | N8: =IF(M8="","",M8-H8) | O8: =IF(M8="","",ABS(M8-H8)*24) | Q8: Binding export saved, mapped to DNS records and certs | R8: N/A — just docs | S8: Watch for SNI, IP-specific bindings, weird ports
A9: 4 | B9: 1 — Discovery | C9: 1.4 | D9: Map Application Dependencies | E9: Find every reference to the current domain — connection strings, API endpoints, OAuth redirect URIs, CORS policies, webhooks, hardcoded URLs. Check web.config, appsettings.json, registry, env vars, and anything external that calls back. | F9: Migration Lead | G9: =ROUND(1*$H$3,0) -> #VALUE! | H9: =$C$3+G9 -> #VALUE! | J9: =IF(I9="Complete",1,IF(I9="Skipped",1,IF(I9="Blocked",0.5,IF(I9="In Progress",0.25,0)))) -> 0 | N9: =IF(M9="","",M9-H9) | O9: =IF(M9="","",ABS(M9-H9)*24) | Q9: Dependency matrix done, every old-domain ref catalogued with file path | R9: N/A — just docs | S9: External services with callback URLs are the ones that bite you
A10: 5 | B10: 1 — Discovery | C10: 1.5 | D10: Map SSO / IdP Configuration | E10: Document current SSO setup — identity provider, protocol (SAML/OIDC), client IDs, redirect URIs, metadata URLs, token endpoints, claim mappings, and any app registrations tied to the domain. If ADFS, pull the relying party trust config. | F10: Migration Lead | G10: =ROUND(1*$H$3,0) -> #VALUE! | H10: =$C$3+G10 -> #VALUE! | J10: =IF(I10="Complete",1,IF(I10="Skipped",1,IF(I10="Blocked",0.5,IF(I10="In Progress",0.25,0)))) -> 0 | N10: =IF(M10="","",M10-H10) | O10: =IF(M10="","",ABS(M10-H10)*24) | Q10: SSO config fully documented — IdP settings, redirect URIs, client IDs, claim maps all captured | R10: N/A — just docs | S10: Dont forget logout/post-logout redirect URIs, they always get missed
A11: 6 | B11: 1 — Discovery | C11: 1.6 | D11: Confirm Static IPs | E11: Verify the VM and DB IPs are static, not DHCP. Document both. No IP change here. | F11: Migration Lead | G11: =ROUND(1*$H$3,0) -> #VALUE! | H11: =$C$3+G11 -> #VALUE! | J11: =IF(I11="Complete",1,IF(I11="Skipped",1,IF(I11="Blocked",0.5,IF(I11="In Progress",0.25,0)))) -> 0 | N11: =IF(M11="","",M11-H11) | O11: =IF(M11="","",ABS(M11-H11)*24) | Q11: ipconfig /all saved, static confirmed for app and DB | R11: N/A — just docs | S11: If DHCP, fix it before anything else
A12: 7 | B12: 1 — Discovery | C12: 1.7 | D12: Check Firewall & Network Rules | E12: Audit firewall rules, NSGs, LB configs for anything referencing the FQDN. Make sure nothing breaks with the new domain. | F12: Network Admin | G12: =ROUND(1*$H$3,0) -> #VALUE! | H12: =$C$3+G12 -> #VALUE! | J12: =IF(I12="Complete",1,IF(I12="Skipped",1,IF(I12="Blocked",0.5,IF(I12="In Progress",0.25,0)))) -> 0 | N12: =IF(M12="","",M12-H12) | O12: =IF(M12="","",ABS(M12-H12)*24) | Q12: All rules reviewed, mitigation plan for any FQDN-dependent rules | R12: N/A — just docs | S12: Some firewalls resolve DNS at rule creation, prefer IP rules
A13: 8 | B13: 1 — Discovery | C13: 1.8 | D13: Get New Certs | E13: Request new certs for target domain from the CA. All required SANs included. Validate the chain is complete — root, intermediate, leaf. | F13: Migration Lead | G13: =ROUND(1*$H$3,0) -> #VALUE! | H13: =$C$3+G13 -> #VALUE! | J13: =IF(I13="Complete",1,IF(I13="Skipped",1,IF(I13="Blocked",0.5,IF(I13="In Progress",0.25,0)))) -> 0 | N13: =IF(M13="","",M13-H13) | O13: =IF(M13="","",ABS(M13-H13)*24) | Q13: PFX in hand, chain validated via certutil, SANs match | R13: Can revert to old cert | S13: If ACME/Lets Encrypt, test issuance in lower env first
A14: 9 | B14: 1 — Discovery | C14: 1.9 | D14: Write Rollback Plan | E14: Step-by-step rollback doc — DNS revert, old cert re-bind, IIS restore, config restore, comms plan. Pre-stage everything. | F14: Migration Lead | G14: =ROUND(2*$H$3,0) -> #VALUE! | H14: =$C$3+G14 -> #VALUE! | J14: =IF(I14="Complete",1,IF(I14="Skipped",1,IF(I14="Blocked",0.5,IF(I14="In Progress",0.25,0)))) -> 0 | N14: =IF(M14="","",M14-H14) | O14: =IF(M14="","",ABS(M14-H14)*24) | Q14: Rollback plan reviewed and approved, all artifacts accessible | R14: N/A — this IS the rollback plan | S14: Pre-write the rollback PowerShell scripts
A15: 10 | B15: 1 — Discovery | C15: 1.10 | D15: Schedule Maintenance Window | E15: Coordinate the migration window. Notify stakeholders, upstream/downstream system owners. | F15: PM | G15: =ROUND(2*$H$3,0) -> #VALUE! | H15: =$C$3+G15 -> #VALUE! | J15: =IF(I15="Complete",1,IF(I15="Skipped",1,IF(I15="Blocked",0.5,IF(I15="In Progress",0.25,0)))) -> 0 | N15: =IF(M15="","",M15-H15) | O15: =IF(M15="","",ABS(M15-H15)*24) | Q15: Calendar invites sent, window approved, everyone acknowledged | R15: N/A | S15: Time zones, business hours, SLA stuff
A16: 11 | B16: 2 — Backups | C16: 2.1 | D16: Backup IIS Config | E16: appcmd add backup. Grab applicationHost.config and all web.configs. | F16: Migration Lead | G16: =ROUND(3*$H$3,0) -> #VALUE! | H16: =$C$3+G16 -> #VALUE! | J16: =IF(I16="Complete",1,IF(I16="Skipped",1,IF(I16="Blocked",0.5,IF(I16="In Progress",0.25,0)))) -> 0 | N16: =IF(M16="","",M16-H16) | O16: =IF(M16="","",ABS(M16-H16)*24) | Q16: Backup verified via dry-run restore, in the repo | R16: Restore IIS from backup | S16: appcmd add backup 'PreMigration'
A17: 12 | B17: 2 — Backups | C17: 2.2 | D17: Export Certs as PFX | E17: Export all relevant certs with private keys as PFX. Store securely, document the passwords separately. | F17: Migration Lead | G17: =ROUND(3*$H$3,0) -> #VALUE! | H17: =$C$3+G17 -> #VALUE! | J17: =IF(I17="Complete",1,IF(I17="Skipped",1,IF(I17="Blocked",0.5,IF(I17="In Progress",0.25,0)))) -> 0 | N17: =IF(M17="","",M17-H17) | O17: =IF(M17="","",ABS(M17-H17)*24) | Q17: PFX files verified importable on test system, in the vault | R17: Re-import old certs from PFX | S17: Export-PfxCertificate with a strong password
A18: 13 | B18: 2 — Backups | C18: 2.3 | D18: Backup App Config | E18: Copy web.config, appsettings.json, env vars, registry keys. Everything. | F18: Migration Lead | G18: =ROUND(3*$H$3,0) -> #VALUE! | H18: =$C$3+G18 -> #VALUE! | J18: =IF(I18="Complete",1,IF(I18="Skipped",1,IF(I18="Blocked",0.5,IF(I18="In Progress",0.25,0)))) -> 0 | N18: =IF(M18="","",M18-H18) | O18: =IF(M18="","",ABS(M18-H18)*24) | Q18: Config backup diffed against live, stored in repo | R18: Restore configs from backup | S18: Include transform files
A19: 14 | B19: 2 — Backups | C19: 2.4 | D19: Backup DNS Records | E19: Export or screenshot DNS records from the provider. Zone file if available. | F19: Migration Lead | G19: =ROUND(3*$H$3,0) -> #VALUE! | H19: =$C$3+G19 -> #VALUE! | J19: =IF(I19="Complete",1,IF(I19="Skipped",1,IF(I19="Blocked",0.5,IF(I19="In Progress",0.25,0)))) -> 0 | N19: =IF(M19="","",M19-H19) | O19: =IF(M19="","",ABS(M19-H19)*24) | Q19: Zone file saved and readable | R19: Revert DNS from backup | S19: Some providers support zone import for quick rollback
A20: 15 | B20: 2 — Backups | C20: 2.5 | D20: Export SSO / IdP Configuration | E20: Export the current IdP app registration, relying party trust, or OIDC client config. Screenshot or export the claim mappings, redirect URIs, and any conditional access policies tied to this app. | F20: Migration Lead | G20: =ROUND(3*$H$3,0) -> #VALUE! | H20: =$C$3+G20 -> #VALUE! | J20: =IF(I20="Complete",1,IF(I20="Skipped",1,IF(I20="Blocked",0.5,IF(I20="In Progress",0.25,0)))) -> 0 | N20: =IF(M20="","",M20-H20) | O20: =IF(M20="","",ABS(M20-H20)*24) | Q20: SSO config export saved alongside other backups, verified re-importable | R20: Restore IdP config from export | S20: Azure AD: export app manifest JSON. ADFS: export relying party trust XML
A21: 16 | B21: 2 — Backups | C21: 2.6 | D21: VM Snapshot | E21: Hypervisor snapshot of the VM. Verify its valid. | F21: Infra Admin | G21: =ROUND(3*$H$3,0) -> #VALUE! | H21: =$C$3+G21 -> #VALUE! | J21: =IF(I21="Complete",1,IF(I21="Skipped",1,IF(I21="Blocked",0.5,IF(I21="In Progress",0.25,0)))) -> 0 | N21: =IF(M21="","",M21-H21) | O21: =IF(M21="","",ABS(M21-H21)*24) | Q21: Snapshot in hypervisor, revert function confirmed | R21: Revert entire VM to snapshot | S21: Nuclear option — make sure theres disk space
A22: 17 | B22: 3 — Cutover | C22: 3.1 | D22: Import New Cert | E22: Import PFX into Local Machine Personal store. Full chain — intermediate + root if needed. | F22: Migration Lead | G22: =ROUND(4*$H$3,0) -> #VALUE! | H22: =$C$3+G22 -> #VALUE! | J22: =IF(I22="Complete",1,IF(I22="Skipped",1,IF(I22="Blocked",0.5,IF(I22="In Progress",0.25,0)))) -> 0 | N22: =IF(M22="","",M22-H22) | O22: =IF(M22="","",ABS(M22-H22)*24) | Q22: Cert visible in certlm.msc, chain shows OK | R22: Remove new cert, old binding stays | S22: Import-PfxCertificate -CertStoreLocation Cert:\LocalMachine\My
A23: 18 | B23: 3 — Cutover | C23: 3.2 | D23: Verify Cert Chain | E23: Make sure the full chain is trusted. Intermediates and root in the right stores. | F23: Migration Lead | G23: =ROUND(4*$H$3,0) -> #VALUE! | H23: =$C$3+G23 -> #VALUE! | J23: =IF(I23="Complete",1,IF(I23="Skipped",1,IF(I23="Blocked",0.5,IF(I23="In Progress",0.25,0)))) -> 0 | N23: =IF(M23="","",M23-H23) | O23: =IF(M23="","",ABS(M23-H23)*24) | Q23: certutil -verify -urlfetch passes clean | R23: Install missing chain certs
A24: 19 | B24: 3 — Cutover | C24: 3.3 | D24: Update IIS Bindings | E24: Swap the HTTPS binding to the new cert and new hostname. Same IP, same port. SNI if applicable. | F24: Migration Lead | G24: =ROUND(4*$H$3,0) -> #VALUE! | H24: =$C$3+G24 -> #VALUE! | J24: =IF(I24="Complete",1,IF(I24="Skipped",1,IF(I24="Blocked",0.5,IF(I24="In Progress",0.25,0)))) -> 0 | N24: =IF(M24="","",M24-H24) | O24: =IF(M24="","",ABS(M24-H24)*24) | Q24: Get-WebBinding shows new cert + hostname, netsh confirms | R24: Revert binding from backup 2.1 | S24: Set-WebBinding + netsh http add sslcert
A25: 20 | B25: 3 — Cutover | C25: 3.4 | D25: Update App Config | E25: Flip all config files to the new domain — base URLs, CORS origins, OAuth redirects, cookie domains, absolute URLs. | F25: Migration Lead | G25: =ROUND(4*$H$3,0) -> #VALUE! | H25: =$C$3+G25 -> #VALUE! | J25: =IF(I25="Complete",1,IF(I25="Skipped",1,IF(I25="Blocked",0.5,IF(I25="In Progress",0.25,0)))) -> 0 | N25: =IF(M25="","",M25-H25) | O25: =IF(M25="","",ABS(M25-H25)*24) | Q25: Config diff shows only expected changes, findstr confirms no old domain refs | R25: Restore from backup 2.3 | S25: grep/findstr for old domain across everything to verify
A26: 21 | B26: 3 — Cutover | C26: 3.5 | D26: Update SSO / IdP Registration | E26: Update the identity provider app registration with new redirect URIs, post-logout URIs, and identifier URIs for the new domain. Update SAML metadata endpoint if applicable. | F26: Migration Lead | G26: =ROUND(4*$H$3,0) -> #VALUE! | H26: =$C$3+G26 -> #VALUE! | J26: =IF(I26="Complete",1,IF(I26="Skipped",1,IF(I26="Blocked",0.5,IF(I26="In Progress",0.25,0)))) -> 0 | N26: =IF(M26="","",M26-H26) | O26: =IF(M26="","",ABS(M26-H26)*24) | Q26: IdP shows correct new-domain URIs, metadata endpoint resolves, no old domain refs | R26: Revert IdP config from backup 2.5 | S26: Azure AD: update redirect URIs. ADFS: update relying party trust. Okta: update app integration URIs
A27: 22 | B27: 3 — Cutover | C27: 3.6 | D27: Update App SSO Config | E27: Update the applications SSO config to match — client metadata URL, authority/issuer, SAML assertion consumer service URL, OIDC redirect URI in web.config or appsettings. Token validation audience needs to match. | F27: Migration Lead | G27: =ROUND(4*$H$3,0) -> #VALUE! | H27: =$C$3+G27 -> #VALUE! | J27: =IF(I27="Complete",1,IF(I27="Skipped",1,IF(I27="Blocked",0.5,IF(I27="In Progress",0.25,0)))) -> 0 | N27: =IF(M27="","",M27-H27) | O27: =IF(M27="","",ABS(M27-H27)*24) | Q27: App SSO config points to correct IdP endpoints with new domain URIs, token audience matches | R27: Restore app config from backup 2.3 | S27: Easy to miss the WS-Federation wtrealm or SAML entityID
A28: 23 | B28: 3 — Cutover | C28: 3.7 | D28: Update DNS | E28: Point the new domain at the VMs IP. Short TTL (60-300s) in lower env, or pre-lowered in prod. | F28: Migration Lead | G28: =ROUND(5*$H$3,0) -> #VALUE! | H28: =$C$3+G28 -> #VALUE! | J28: =IF(I28="Complete",1,IF(I28="Skipped",1,IF(I28="Blocked",0.5,IF(I28="In Progress",0.25,0)))) -> 0 | N28: =IF(M28="","",M28-H28) | O28: =IF(M28="","",ABS(M28-H28)*24) | Q28: nslookup resolves new domain to correct IP | R28: Revert DNS from backup 2.4 | S28: Prod: lower TTL 24-48hrs ahead (see 5.1)
A29: 24 | B29: 3 — Cutover | C29: 3.8 | D29: Restart IIS | E29: iisreset, recycle the app pool. Pick up all changes cleanly. | F29: Migration Lead | G29: =ROUND(5*$H$3,0) -> #VALUE! | H29: =$C$3+G29 -> #VALUE! | J29: =IF(I29="Complete",1,IF(I29="Skipped",1,IF(I29="Blocked",0.5,IF(I29="In Progress",0.25,0)))) -> 0 | N29: =IF(M29="","",M29-H29) | O29: =IF(M29="","",ABS(M29-H29)*24) | Q29: Site running, app pool started, Event Viewer clean | R29: N/A — non-destructive | S29: Brief downtime during iisreset
A30: 25 | B30: 3 — Cutover | C30: 3.9 | D30: Verify DNS Propagation | E30: Check propagation across multiple resolvers. Dont move on until its solid. | F30: Migration Lead | G30: =ROUND(5*$H$3,0) -> #VALUE! | H30: =$C$3+G30 -> #VALUE! | J30: =IF(I30="Complete",1,IF(I30="Skipped",1,IF(I30="Blocked",0.5,IF(I30="In Progress",0.25,0)))) -> 0 | N30: =IF(M30="","",M30-H30) | O30: =IF(M30="","",ABS(M30-H30)*24) | Q30: Resolves from 3+ external resolvers and 2+ regions | R30: Wait or investigate cached TTL | S30: nslookup 8.8.8.8, 1.1.1.1, whatsmydns.net
A31: 26 | B31: 4 — Testing | C31: 4.1 | D31: Run Test Scripts | E31: Execute the full test suite — HTTPS/cert, redirects, auth flow including SSO login + 2FA, CRUD, DB connectivity, APIs, webhooks, email links, perf baseline, security scan. | F31: QA Lead | G31: =ROUND(6*$H$3,0) -> #VALUE! | H31: =$C$3+G31 -> #VALUE! | J31: =IF(I31="Complete",1,IF(I31="Skipped",1,IF(I31="Blocked",0.5,IF(I31="In Progress",0.25,0)))) -> 0 | N31: =IF(M31="","",M31-H31) | O31: =IF(M31="","",ABS(M31-H31)*24) | Q31: All scripts executed, results recorded, pass/fail documented per script | R31: Log failures, categorize migration vs pre-existing | S31: Update JIRA and this sheet with results
A32: 27 | B32: 4 — Testing | C32: 4.2 | D32: SSO End-to-End Validation | E32: Test the full SSO flow — IdP-initiated and SP-initiated login, token validation, claim mapping, group/role assignment, logout + single logout, session timeout, conditional access. | F32: QA Lead | G32: =ROUND(6*$H$3,0) -> #VALUE! | H32: =$C$3+G32 -> #VALUE! | J32: =IF(I32="Complete",1,IF(I32="Skipped",1,IF(I32="Blocked",0.5,IF(I32="In Progress",0.25,0)))) -> 0 | N32: =IF(M32="","",M32-H32) | O32: =IF(M32="","",ABS(M32-H32)*24) | Q32: SSO works both directions, claims correct, logout cleans sessions, no old domain in any redirect | R32: Check IdP logs for failed assertions or redirect mismatches | S32: Hit IdP login directly AND from the app, both need to work
A33: 28 | B33: 4 — Testing | C33: 4.3 | D33: Triage & Fix | E33: Review all failures. Migration-caused vs pre-existing. Fix whats ours, re-run the failed tests. | F33: Migration Lead | G33: =ROUND(7*$H$3,0) -> #VALUE! | H33: =$C$3+G33 -> #VALUE! | J33: =IF(I33="Complete",1,IF(I33="Skipped",1,IF(I33="Blocked",0.5,IF(I33="In Progress",0.25,0)))) -> 0 | N33: =IF(M33="","",M33-H33) | O33: =IF(M33="","",ABS(M33-H33)*24) | Q33: All migration defects fixed, re-runs pass, pre-existing issues documented | R33: If unfixable, assess rollback | S33: Pull in app team for code-level fixes if needed
A34: 29 | B34: 4 — Testing | C34: 4.4 | D34: Update JIRA & This Sheet | E34: Get JIRA current with test results, defect resolutions, evidence. Update Status column here for every task. | F34: QA Lead | G34: =ROUND(8*$H$3,0) -> #VALUE! | H34: =$C$3+G34 -> #VALUE! | J34: =IF(I34="Complete",1,IF(I34="Skipped",1,IF(I34="Blocked",0.5,IF(I34="In Progress",0.25,0)))) -> 0 | N34: =IF(M34="","",M34-H34) | O34: =IF(M34="","",ABS(M34-H34)*24) | Q34: JIRA tickets current, this sheet reflects actual status, evidence attached | R34: N/A — just docs | S34: Screenshots, logs, test exports attached to tickets
A35: 30 | B35: 4 — Testing | C35: 4.5 | D35: Sign-Off | E35: Collect results. Get formal sign-off from QA, app owner, stakeholders. | F35: PM | G35: =ROUND(8*$H$3,0) -> #VALUE! | H35: =$C$3+G35 -> #VALUE! | J35: =IF(I35="Complete",1,IF(I35="Skipped",1,IF(I35="Blocked",0.5,IF(I35="In Progress",0.25,0)))) -> 0 | N35: =IF(M35="","",M35-H35) | O35: =IF(M35="","",ABS(M35-H35)*24) | Q35: Written sign-off, all critical/high defects resolved, accepted risks documented | R35: Dont proceed, fix outstanding issues
A36: 31 | B36: 5 — Pre-Prod Prep | C36: 5.1 | D36: Lower Prod DNS TTL (24-48hrs Early) | E36: Drop TTL on the existing prod DNS record to 60-300s. At least 24-48hrs before the migration window. | F36: Migration Lead | G36: =ROUND(9*$H$3,0) -> #VALUE! | H36: =$C$3+G36 -> #VALUE! | J36: =IF(I36="Complete",1,IF(I36="Skipped",1,IF(I36="Blocked",0.5,IF(I36="In Progress",0.25,0)))) -> 0 | N36: =IF(M36="","",M36-H36) | O36: =IF(M36="","",ABS(M36-H36)*24) | Q36: dig shows reduced TTL, waited 2x old TTL | R36: Raise TTL back | S36: This MUST happen in advance, not day-of
A37: 32 | B37: 5 — Pre-Prod Prep | C37: 5.2 | D37: Confirm Window Is Active | E37: Verify the maintenance window is live. Final notification to stakeholders. On-call confirmed. | F37: PM | G37: =ROUND(10*$H$3,0) -> #VALUE! | H37: =$C$3+G37 -> #VALUE! | J37: =IF(I37="Complete",1,IF(I37="Skipped",1,IF(I37="Blocked",0.5,IF(I37="In Progress",0.25,0)))) -> 0 | N37: =IF(M37="","",M37-H37) | O37: =IF(M37="","",ABS(M37-H37)*24) | Q37: Notification sent, status page updated, on-call team confirmed | R37: Cancel window, send all-clear
A38: 33 | B38: 5 — Pre-Prod Prep | C38: 5.3 | D38: Prod VM Snapshot | E38: Snapshot immediately before touching anything. | F38: Infra Admin | G38: =ROUND(10*$H$3,0) -> #VALUE! | H38: =$C$3+G38 -> #VALUE! | J38: =IF(I38="Complete",1,IF(I38="Skipped",1,IF(I38="Blocked",0.5,IF(I38="In Progress",0.25,0)))) -> 0 | N38: =IF(M38="","",M38-H38) | O38: =IF(M38="","",ABS(M38-H38)*24) | Q38: Snapshot verified in hypervisor | R38: Revert to snapshot | S38: Check disk space first
A39: 34 | B39: 5 — Pre-Prod Prep | C39: 5.4 | D39: Backup Prod IIS, Certs, SSO & Config | E39: Repeat Phase 2 backup steps on production. | F39: Migration Lead | G39: =ROUND(10*$H$3,0) -> #VALUE! | H39: =$C$3+G39 -> #VALUE! | J39: =IF(I39="Complete",1,IF(I39="Skipped",1,IF(I39="Blocked",0.5,IF(I39="In Progress",0.25,0)))) -> 0 | N39: =IF(M39="","",M39-H39) | O39: =IF(M39="","",ABS(M39-H39)*24) | Q39: All backups created, verified, labelled with timestamp | R39: Restore from these backups
A40: 35 | B40: 6 — Prod Cutover | C40: 6.1 | D40: Execute Phase 3 on Production | E40: Run steps 3.1 through 3.9 on the prod VM. Exact same procedures validated in testing. No freelancing. | F40: Migration Lead | G40: =ROUND(10*$H$3,0) -> #VALUE! | H40: =$C$3+G40 -> #VALUE! | J40: =IF(I40="Complete",1,IF(I40="Skipped",1,IF(I40="Blocked",0.5,IF(I40="In Progress",0.25,0)))) -> 0 | N40: =IF(M40="","",M40-H40) | O40: =IF(M40="","",ABS(M40-H40)*24) | Q40: Cert, bindings, app config, SSO config, DNS all updated, IIS restarted, propagation confirmed | R40: Revert per rollback plan 1.9 | S40: Follow the validated playbook exactly
A41: 36 | B41: 7 — Prod Smoke | C41: 7.1 | D41: Run Smoke Scripts on Prod | E41: Smoke test subset against prod — HTTPS, redirects, SSO login (IdP and SP initiated), critical reads, critical writes, top APIs, external integrations, monitoring. | F41: QA Lead | G41: =ROUND(11*$H$3,0) -> #VALUE! | H41: =$C$3+G41 -> #VALUE! | J41: =IF(I41="Complete",1,IF(I41="Skipped",1,IF(I41="Blocked",0.5,IF(I41="In Progress",0.25,0)))) -> 0 | N41: =IF(M41="","",M41-H41) | O41: =IF(M41="","",ABS(M41-H41)*24) | Q41: All smoke scripts pass, results in JIRA and this sheet | R41: Log failures, assess rollback severity | S41: External network, multiple browsers, at least one mobile
A42: 37 | B42: 7 — Prod Smoke | C42: 7.2 | D42: Smoke Defect Triage | E42: Review failures. Fix immediately or pull the trigger on rollback. | F42: Migration Lead | G42: =ROUND(11*$H$3,0) -> #VALUE! | H42: =$C$3+G42 -> #VALUE! | J42: =IF(I42="Complete",1,IF(I42="Skipped",1,IF(I42="Blocked",0.5,IF(I42="In Progress",0.25,0)))) -> 0 | N42: =IF(M42="","",M42-H42) | O42: =IF(M42="","",ABS(M42-H42)*24) | Q42: All failures triaged, fixes applied or rollback initiated | R42: Execute rollback plan 1.9 | S42: Everyone on the call for this
...

Sheet Project 3
A1: =IF(Config!B8<>"",Config!B8&" — DNS, Certificate & SSO Migration Runbook","Project 3 — Assign name on Config sheet") -> Project 3 — Assign name on Config sheet
A3: Start Date: | C3: =Config!C8 -> 0 | D3: Speed: | E3: =Config!D8 -> 0 | G3: Mult: | H3: =Config!E8 | I3: Target End: | K3: =Config!F8 | L3: Days: | M3: =Config!G8
A5: # | B5: Phase | C5: ID | D5: Task | E5: What Needs to Happen | F5: Owner | G5: Day | H5: Target Date | I5: Status | J5: % Complete | K5: Signed Off By | L5: Report Link | M5: Completed | N5: Drift | O5: Hrs | P5: JIRA | Q5: How We Know Its Done | R5: Rollback | S5: Notes
A6: 1 | B6: 1 — Discovery | C6: 1.1 | D6: Pull DNS Records | E6: Export all DNS records for the app domain — A, CNAME, MX, TXT, SRV, the works. Grab zone files from the provider. Document TTLs and anything pointing at a CDN or WAF. | F6: Migration Lead | G6: =ROUND(0*$H$3,0) -> #VALUE! | H6: =$C$3+G6 -> #VALUE! | J6: =IF(I6="Complete",1,IF(I6="Skipped",1,IF(I6="Blocked",0.5,IF(I6="In Progress",0.25,0)))) -> 0 | N6: =IF(M6="","",M6-H6) | O6: =IF(M6="","",ABS(M6-H6)*24) | Q6: Full DNS export in the repo, second set of eyes confirmed it | R6: N/A — just docs | S6: Get TTLs, record types, CDN refs
A7: 2 | B7: 1 — Discovery | C7: 1.2 | D7: Pull Current Certs | E7: Document every cert bound in IIS — subject, SANs, issuer, expiry, thumbprint. PowerShell: Get-ChildItem Cert:\LocalMachine\My | F7: Migration Lead | G7: =ROUND(0*$H$3,0) -> #VALUE! | H7: =$C$3+G7 -> #VALUE! | J7: =IF(I7="Complete",1,IF(I7="Skipped",1,IF(I7="Blocked",0.5,IF(I7="In Progress",0.25,0)))) -> 0 | N7: =IF(M7="","",M7-H7) | O7: =IF(M7="","",ABS(M7-H7)*24) | Q7: Cert inventory with thumbprints, SANs, expiry confirmed | R7: N/A — just docs | S7: Flag wildcards, intermediates, shared certs
A8: 3 | B8: 1 — Discovery | C8: 1.3 | D8: Export IIS Bindings | E8: Dump all IIS site bindings — IP, port, hostname, cert assignment. Get-WebBinding or appcmd. Both HTTP and HTTPS. | F8: Migration Lead | G8: =ROUND(0*$H$3,0) -> #VALUE! | H8: =$C$3+G8 -> #VALUE! | J8: =IF(I8="Complete",1,IF(I8="Skipped",1,IF(I8="Blocked",0.5,IF(I8="In Progress",0.25,0)))) -> 0 | N8: =IF(M8="","",M8-H8) | O8: =IF(M8="","",ABS(M8-H8)*24) | Q8: Binding export saved, mapped to DNS records and certs | R8: N/A — just docs | S8: Watch for SNI, IP-specific bindings, weird ports
A9: 4 | B9: 1 — Discovery | C9: 1.4 | D9: Map Application Dependencies | E9: Find every reference to the current domain — connection strings, API endpoints, OAuth redirect URIs, CORS policies, webhooks, hardcoded URLs. Check web.config, appsettings.json, registry, env vars, and anything external that calls back. | F9: Migration Lead | G9: =ROUND(1*$H$3,0) -> #VALUE! | H9: =$C$3+G9 -> #VALUE! | J9: =IF(I9="Complete",1,IF(I9="Skipped",1,IF(I9="Blocked",0.5,IF(I9="In Progress",0.25,0)))) -> 0 | N9: =IF(M9="","",M9-H9) | O9: =IF(M9="","",ABS(M9-H9)*24) | Q9: Dependency matrix done, every old-domain ref catalogued with file path | R9: N/A — just docs | S9: External services with callback URLs are the ones that bite you
A10: 5 | B10: 1 — Discovery | C10: 1.5 | D10: Map SSO / IdP Configuration | E10: Document current SSO setup — identity provider, protocol (SAML/OIDC), client IDs, redirect URIs, metadata URLs, token endpoints, claim mappings, and any app registrations tied to the domain. If ADFS, pull the relying party trust config. | F10: Migration Lead | G10: =ROUND(1*$H$3,0) -> #VALUE! | H10: =$C$3+G10 -> #VALUE! | J10: =IF(I10="Complete",1,IF(I10="Skipped",1,IF(I10="Blocked",0.5,IF(I10="In Progress",0.25,0)))) -> 0 | N10: =IF(M10="","",M10-H10) | O10: =IF(M10="","",ABS(M10-H10)*24) | Q10: SSO config fully documented — IdP settings, redirect URIs, client IDs, claim maps all captured | R10: N/A — just docs | S10: Dont forget logout/post-logout redirect URIs, they always get missed
A11: 6 | B11: 1 — Discovery | C11: 1.6 | D11: Confirm Static IPs | E11: Verify the VM and DB IPs are static, not DHCP. Document both. No IP change here. | F11: Migration Lead | G11: =ROUND(1*$H$3,0) -> #VALUE! | H11: =$C$3+G11 -> #VALUE! | J11: =IF(I11="Complete",1,IF(I11="Skipped",1,IF(I11="Blocked",0.5,IF(I11="In Progress",0.25,0)))) -> 0 | N11: =IF(M11="","",M11-H11) | O11: =IF(M11="","",ABS(M11-H11)*24) | Q11: ipconfig /all saved, static confirmed for app and DB | R11: N/A — just docs | S11: If DHCP, fix it before anything else
A12: 7 | B12: 1 — Discovery | C12: 1.7 | D12: Check Firewall & Network Rules | E12: Audit firewall rules, NSGs, LB configs for anything referencing the FQDN. Make sure nothing breaks with the new domain. | F12: Network Admin | G12: =ROUND(1*$H$3,0) -> #VALUE! | H12: =$C$3+G12 -> #VALUE! | J12: =IF(I12="Complete",1,IF(I12="Skipped",1,IF(I12="Blocked",0.5,IF(I12="In Progress",0.25,0)))) -> 0 | N12: =IF(M12="","",M12-H12) | O12: =IF(M12="","",ABS(M12-H12)*24) | Q12: All rules reviewed, mitigation plan for any FQDN-dependent rules | R12: N/A — just docs | S12: Some firewalls resolve DNS at rule creation, prefer IP rules
A13: 8 | B13: 1 — Discovery | C13: 1.8 | D13: Get New Certs | E13: Request new certs for target domain from the CA. All required SANs included. Validate the chain is complete — root, intermediate, leaf. | F13: Migration Lead | G13: =ROUND(1*$H$3,0) -> #VALUE! | H13: =$C$3+G13 -> #VALUE! | J13: =IF(I13="Complete",1,IF(I13="Skipped",1,IF(I13="Blocked",0.5,IF(I13="In Progress",0.25,0)))) -> 0 | N13: =IF(M13="","",M13-H13) | O13: =IF(M13="","",ABS(M13-H13)*24) | Q13: PFX in hand, chain validated via certutil, SANs match | R13: Can revert to old cert | S13: If ACME/Lets Encrypt, test issuance in lower env first
A14: 9 | B14: 1 — Discovery | C14: 1.9 | D14: Write Rollback Plan | E14: Step-by-step rollback doc — DNS revert, old cert re-bind, IIS restore, config restore, comms plan. Pre-stage everything. | F14: Migration Lead | G14: =ROUND(2*$H$3,0) -> #VALUE! | H14: =$C$3+G14 -> #VALUE! | J14: =IF(I14="Complete",1,IF(I14="Skipped",1,IF(I14="Blocked",0.5,IF(I14="In Progress",0.25,0)))) -> 0 | N14: =IF(M14="","",M14-H14) | O14: =IF(M14="","",ABS(M14-H14)*24) | Q14: Rollback plan reviewed and approved, all artifacts accessible | R14: N/A — this IS the rollback plan | S14: Pre-write the rollback PowerShell scripts
A15: 10 | B15: 1 — Discovery | C15: 1.10 | D15: Schedule Maintenance Window | E15: Coordinate the migration window. Notify stakeholders, upstream/downstream system owners. | F15: PM | G15: =ROUND(2*$H$3,0) -> #VALUE! | H15: =$C$3+G15 -> #VALUE! | J15: =IF(I15="Complete",1,IF(I15="Skipped",1,IF(I15="Blocked",0.5,IF(I15="In Progress",0.25,0)))) -> 0 | N15: =IF(M15="","",M15-H15) | O15: =IF(M15="","",ABS(M15-H15)*24) | Q15: Calendar invites sent, window approved, everyone acknowledged | R15: N/A | S15: Time zones, business hours, SLA stuff
A16: 11 | B16: 2 — Backups | C16: 2.1 | D16: Backup IIS Config | E16: appcmd add backup. Grab applicationHost.config and all web.configs. | F16: Migration Lead | G16: =ROUND(3*$H$3,0) -> #VALUE! | H16: =$C$3+G16 -> #VALUE! | J16: =IF(I16="Complete",1,IF(I16="Skipped",1,IF(I16="Blocked",0.5,IF(I16="In Progress",0.25,0)))) -> 0 | N16: =IF(M16="","",M16-H16) | O16: =IF(M16="","",ABS(M16-H16)*24) | Q16: Backup verified via dry-run restore, in the repo | R16: Restore IIS from backup | S16: appcmd add backup 'PreMigration'
A17: 12 | B17: 2 — Backups | C17: 2.2 | D17: Export Certs as PFX | E17: Export all relevant certs with private keys as PFX. Store securely, document the passwords separately. | F17: Migration Lead | G17: =ROUND(3*$H$3,0) -> #VALUE! | H17: =$C$3+G17 -> #VALUE! | J17: =IF(I17="Complete",1,IF(I17="Skipped",1,IF(I17="Blocked",0.5,IF(I17="In Progress",0.25,0)))) -> 0 | N17: =IF(M17="","",M17-H17) | O17: =IF(M17="","",ABS(M17-H17)*24) | Q17: PFX files verified importable on test system, in the vault | R17: Re-import old certs from PFX | S17: Export-PfxCertificate with a strong password
A18: 13 | B18: 2 — Backups | C18: 2.3 | D18: Backup App Config | E18: Copy web.config, appsettings.json, env vars, registry keys. Everything. | F18: Migration Lead | G18: =ROUND(3*$H$3,0) -> #VALUE! | H18: =$C$3+G18 -> #VALUE! | J18: =IF(I18="Complete",1,IF(I18="Skipped",1,IF(I18="Blocked",0.5,IF(I18="In Progress",0.25,0)))) -> 0 | N18: =IF(M18="","",M18-H18) | O18: =IF(M18="","",ABS(M18-H18)*24) | Q18: Config backup diffed against live, stored in repo | R18: Restore configs from backup | S18: Include transform files
A19: 14 | B19: 2 — Backups | C19: 2.4 | D19: Backup DNS Records | E19: Export or screenshot DNS records from the provider. Zone file if available. | F19: Migration Lead | G19: =ROUND(3*$H$3,0) -> #VALUE! | H19: =$C$3+G19 -> #VALUE! | J19: =IF(I19="Complete",1,IF(I19="Skipped",1,IF(I19="Blocked",0.5,IF(I19="In Progress",0.25,0)))) -> 0 | N19: =IF(M19="","",M19-H19) | O19: =IF(M19="","",ABS(M19-H19)*24) | Q19: Zone file saved and readable | R19: Revert DNS from backup | S19: Some providers support zone import for quick rollback
A20: 15 | B20: 2 — Backups | C20: 2.5 | D20: Export SSO / IdP Configuration | E20: Export the current IdP app registration, relying party trust, or OIDC client config. Screenshot or export the claim mappings, redirect URIs, and any conditional access policies tied to this app. | F20: Migration Lead | G20: =ROUND(3*$H$3,0) -> #VALUE! | H20: =$C$3+G20 -> #VALUE! | J20: =IF(I20="Complete",1,IF(I20="Skipped",1,IF(I20="Blocked",0.5,IF(I20="In Progress",0.25,0)))) -> 0 | N20: =IF(M20="","",M20-H20) | O20: =IF(M20="","",ABS(M20-H20)*24) | Q20: SSO config export saved alongside other backups, verified re-importable | R20: Restore IdP config from export | S20: Azure AD: export app manifest JSON. ADFS: export relying party trust XML
